
Performing system checks...

System check identified no issues (0 silenced).

You have unapplied migrations; your app may not work properly until they are applied.
Run 'python manage.py migrate' to apply them.
May 24, 2016 - 13:19:41
Django version 1.9.5, using settings 'CI103.settings'
Starting development server at http://127.0.0.1:8000/
Quit the server with CONTROL-C.
Unhandled exception in thread started by <function check_errors.<locals>.wrapper at 0x7ff9777400d0>
Traceback (most recent call last):
  File "/usr/lib/python3.4/site-packages/django/db/backends/postgresql/base.py", line 20, in <module>
    import psycopg2 as Database
ImportError: No module named 'psycopg2'

During handling of the above exception, another exception occurred:

Traceback (most recent call last):
  File "/usr/lib/python3.4/site-packages/django/utils/autoreload.py", line 226, in wrapper
    fn(*args, **kwargs)
  File "/usr/lib/python3.4/site-packages/django/core/management/commands/runserver.py", line 109, in inner_run
    autoreload.raise_last_exception()
  File "/usr/lib/python3.4/site-packages/django/utils/autoreload.py", line 249, in raise_last_exception
    six.reraise(*_exception)
  File "/usr/lib/python3.4/site-packages/django/utils/six.py", line 685, in reraise
    raise value.with_traceback(tb)
  File "/usr/lib/python3.4/site-packages/django/utils/autoreload.py", line 226, in wrapper
    fn(*args, **kwargs)
  File "/usr/lib/python3.4/site-packages/django/__init__.py", line 18, in setup
    apps.populate(settings.INSTALLED_APPS)
  File "/usr/lib/python3.4/site-packages/django/apps/registry.py", line 108, in populate
    app_config.import_models(all_models)
  File "/usr/lib/python3.4/site-packages/django/apps/config.py", line 202, in import_models
    self.models_module = import_module(models_module_name)
  File "/usr/lib64/python3.4/importlib/__init__.py", line 109, in import_module
    return _bootstrap._gcd_import(name[level:], package, level)
  File "<frozen importlib._bootstrap>", line 2254, in _gcd_import
  File "<frozen importlib._bootstrap>", line 2237, in _find_and_load
  File "<frozen importlib._bootstrap>", line 2226, in _find_and_load_unlocked
  File "<frozen importlib._bootstrap>", line 1200, in _load_unlocked
  File "<frozen importlib._bootstrap>", line 1129, in _exec
  File "<frozen importlib._bootstrap>", line 1471, in exec_module
  File "<frozen importlib._bootstrap>", line 321, in _call_with_frames_removed
  File "/usr/lib/python3.4/site-packages/django/contrib/auth/models.py", line 4, in <module>
    from django.contrib.auth.base_user import AbstractBaseUser, BaseUserManager
  File "/usr/lib/python3.4/site-packages/django/contrib/auth/base_user.py", line 49, in <module>
    class AbstractBaseUser(models.Model):
  File "/usr/lib/python3.4/site-packages/django/db/models/base.py", line 108, in __new__
    new_class.add_to_class('_meta', Options(meta, app_label))
  File "/usr/lib/python3.4/site-packages/django/db/models/base.py", line 307, in add_to_class
    value.contribute_to_class(cls, name)
  File "/usr/lib/python3.4/site-packages/django/db/models/options.py", line 263, in contribute_to_class
    self.db_table = truncate_name(self.db_table, connection.ops.max_name_length())
  File "/usr/lib/python3.4/site-packages/django/db/__init__.py", line 36, in __getattr__
    return getattr(connections[DEFAULT_DB_ALIAS], item)
  File "/usr/lib/python3.4/site-packages/django/db/utils.py", line 212, in __getitem__
    backend = load_backend(db['ENGINE'])
  File "/usr/lib/python3.4/site-packages/django/db/utils.py", line 116, in load_backend
    return import_module('%s.base' % backend_name)
  File "/usr/lib64/python3.4/importlib/__init__.py", line 109, in import_module
    return _bootstrap._gcd_import(name[level:], package, level)
  File "/usr/lib/python3.4/site-packages/django/db/backends/postgresql/base.py", line 24, in <module>
    raise ImproperlyConfigured("Error loading psycopg2 module: %s" % e)
django.core.exceptions.ImproperlyConfigured: Error loading psycopg2 module: No module named 'psycopg2'
Unhandled exception in thread started by <function check_errors.<locals>.wrapper at 0x7f13c91300d0>
Traceback (most recent call last):
  File "/usr/lib/python3.4/site-packages/django/db/backends/postgresql/base.py", line 20, in <module>
    import psycopg2 as Database
ImportError: No module named 'psycopg2'

During handling of the above exception, another exception occurred:

Traceback (most recent call last):
  File "/usr/lib/python3.4/site-packages/django/utils/autoreload.py", line 226, in wrapper
    fn(*args, **kwargs)
  File "/usr/lib/python3.4/site-packages/django/core/management/commands/runserver.py", line 109, in inner_run
    autoreload.raise_last_exception()
  File "/usr/lib/python3.4/site-packages/django/utils/autoreload.py", line 249, in raise_last_exception
    six.reraise(*_exception)
  File "/usr/lib/python3.4/site-packages/django/utils/six.py", line 685, in reraise
    raise value.with_traceback(tb)
  File "/usr/lib/python3.4/site-packages/django/utils/autoreload.py", line 226, in wrapper
    fn(*args, **kwargs)
  File "/usr/lib/python3.4/site-packages/django/__init__.py", line 18, in setup
    apps.populate(settings.INSTALLED_APPS)
  File "/usr/lib/python3.4/site-packages/django/apps/registry.py", line 108, in populate
    app_config.import_models(all_models)
  File "/usr/lib/python3.4/site-packages/django/apps/config.py", line 202, in import_models
    self.models_module = import_module(models_module_name)
  File "/usr/lib64/python3.4/importlib/__init__.py", line 109, in import_module
    return _bootstrap._gcd_import(name[level:], package, level)
  File "<frozen importlib._bootstrap>", line 2254, in _gcd_import
  File "<frozen importlib._bootstrap>", line 2237, in _find_and_load
  File "<frozen importlib._bootstrap>", line 2226, in _find_and_load_unlocked
  File "<frozen importlib._bootstrap>", line 1200, in _load_unlocked
  File "<frozen importlib._bootstrap>", line 1129, in _exec
  File "<frozen importlib._bootstrap>", line 1471, in exec_module
  File "<frozen importlib._bootstrap>", line 321, in _call_with_frames_removed
  File "/usr/lib/python3.4/site-packages/django/contrib/auth/models.py", line 4, in <module>
    from django.contrib.auth.base_user import AbstractBaseUser, BaseUserManager
  File "/usr/lib/python3.4/site-packages/django/contrib/auth/base_user.py", line 49, in <module>
    class AbstractBaseUser(models.Model):
  File "/usr/lib/python3.4/site-packages/django/db/models/base.py", line 108, in __new__
    new_class.add_to_class('_meta', Options(meta, app_label))
  File "/usr/lib/python3.4/site-packages/django/db/models/base.py", line 307, in add_to_class
    value.contribute_to_class(cls, name)
  File "/usr/lib/python3.4/site-packages/django/db/models/options.py", line 263, in contribute_to_class
    self.db_table = truncate_name(self.db_table, connection.ops.max_name_length())
  File "/usr/lib/python3.4/site-packages/django/db/__init__.py", line 36, in __getattr__
    return getattr(connections[DEFAULT_DB_ALIAS], item)
  File "/usr/lib/python3.4/site-packages/django/db/utils.py", line 212, in __getitem__
    backend = load_backend(db['ENGINE'])
  File "/usr/lib/python3.4/site-packages/django/db/utils.py", line 116, in load_backend
    return import_module('%s.base' % backend_name)
  File "/usr/lib64/python3.4/importlib/__init__.py", line 109, in import_module
    return _bootstrap._gcd_import(name[level:], package, level)
  File "/usr/lib/python3.4/site-packages/django/db/backends/postgresql/base.py", line 24, in <module>
    raise ImproperlyConfigured("Error loading psycopg2 module: %s" % e)
django.core.exceptions.ImproperlyConfigured: Error loading psycopg2 module: No module named 'psycopg2'
Unhandled exception in thread started by <function check_errors.<locals>.wrapper at 0x7f87e7d230d0>
Traceback (most recent call last):
  File "/usr/lib/python3.4/site-packages/django/db/backends/postgresql/base.py", line 20, in <module>
    import psycopg2 as Database
ImportError: No module named 'psycopg2'

During handling of the above exception, another exception occurred:

Traceback (most recent call last):
  File "/usr/lib/python3.4/site-packages/django/utils/autoreload.py", line 226, in wrapper
    fn(*args, **kwargs)
  File "/usr/lib/python3.4/site-packages/django/core/management/commands/runserver.py", line 109, in inner_run
    autoreload.raise_last_exception()
  File "/usr/lib/python3.4/site-packages/django/utils/autoreload.py", line 249, in raise_last_exception
    six.reraise(*_exception)
  File "/usr/lib/python3.4/site-packages/django/utils/six.py", line 685, in reraise
    raise value.with_traceback(tb)
  File "/usr/lib/python3.4/site-packages/django/utils/autoreload.py", line 226, in wrapper
    fn(*args, **kwargs)
  File "/usr/lib/python3.4/site-packages/django/__init__.py", line 18, in setup
    apps.populate(settings.INSTALLED_APPS)
  File "/usr/lib/python3.4/site-packages/django/apps/registry.py", line 108, in populate
    app_config.import_models(all_models)
  File "/usr/lib/python3.4/site-packages/django/apps/config.py", line 202, in import_models
    self.models_module = import_module(models_module_name)
  File "/usr/lib64/python3.4/importlib/__init__.py", line 109, in import_module
    return _bootstrap._gcd_import(name[level:], package, level)
  File "<frozen importlib._bootstrap>", line 2254, in _gcd_import
  File "<frozen importlib._bootstrap>", line 2237, in _find_and_load
  File "<frozen importlib._bootstrap>", line 2226, in _find_and_load_unlocked
  File "<frozen importlib._bootstrap>", line 1200, in _load_unlocked
  File "<frozen importlib._bootstrap>", line 1129, in _exec
  File "<frozen importlib._bootstrap>", line 1471, in exec_module
  File "<frozen importlib._bootstrap>", line 321, in _call_with_frames_removed
  File "/usr/lib/python3.4/site-packages/django/contrib/auth/models.py", line 4, in <module>
    from django.contrib.auth.base_user import AbstractBaseUser, BaseUserManager
  File "/usr/lib/python3.4/site-packages/django/contrib/auth/base_user.py", line 49, in <module>
    class AbstractBaseUser(models.Model):
  File "/usr/lib/python3.4/site-packages/django/db/models/base.py", line 108, in __new__
    new_class.add_to_class('_meta', Options(meta, app_label))
  File "/usr/lib/python3.4/site-packages/django/db/models/base.py", line 307, in add_to_class
    value.contribute_to_class(cls, name)
  File "/usr/lib/python3.4/site-packages/django/db/models/options.py", line 263, in contribute_to_class
    self.db_table = truncate_name(self.db_table, connection.ops.max_name_length())
  File "/usr/lib/python3.4/site-packages/django/db/__init__.py", line 36, in __getattr__
    return getattr(connections[DEFAULT_DB_ALIAS], item)
  File "/usr/lib/python3.4/site-packages/django/db/utils.py", line 212, in __getitem__
    backend = load_backend(db['ENGINE'])
  File "/usr/lib/python3.4/site-packages/django/db/utils.py", line 116, in load_backend
    return import_module('%s.base' % backend_name)
  File "/usr/lib64/python3.4/importlib/__init__.py", line 109, in import_module
    return _bootstrap._gcd_import(name[level:], package, level)
  File "/usr/lib/python3.4/site-packages/django/db/backends/postgresql/base.py", line 24, in <module>
    raise ImproperlyConfigured("Error loading psycopg2 module: %s" % e)
django.core.exceptions.ImproperlyConfigured: Error loading psycopg2 module: No module named 'psycopg2'
Unhandled exception in thread started by <function check_errors.<locals>.wrapper at 0x7f190c2a2e18>
Traceback (most recent call last):
  File "/usr/lib/python3.4/site-packages/django/apps/config.py", line 118, in create
    cls = getattr(mod, cls_name)
AttributeError: 'module' object has no attribute 'homebaseConfig'

During handling of the above exception, another exception occurred:

Traceback (most recent call last):
  File "<frozen importlib._bootstrap>", line 2218, in _find_and_load_unlocked
AttributeError: 'module' object has no attribute '__path__'

During handling of the above exception, another exception occurred:

Traceback (most recent call last):
  File "/usr/lib/python3.4/site-packages/django/utils/autoreload.py", line 226, in wrapper
    fn(*args, **kwargs)
  File "/usr/lib/python3.4/site-packages/django/core/management/commands/runserver.py", line 109, in inner_run
    autoreload.raise_last_exception()
  File "/usr/lib/python3.4/site-packages/django/utils/autoreload.py", line 249, in raise_last_exception
    six.reraise(*_exception)
  File "/usr/lib/python3.4/site-packages/django/utils/six.py", line 685, in reraise
    raise value.with_traceback(tb)
  File "/usr/lib/python3.4/site-packages/django/utils/autoreload.py", line 226, in wrapper
    fn(*args, **kwargs)
  File "/usr/lib/python3.4/site-packages/django/__init__.py", line 18, in setup
    apps.populate(settings.INSTALLED_APPS)
  File "/usr/lib/python3.4/site-packages/django/apps/registry.py", line 85, in populate
    app_config = AppConfig.create(entry)
  File "/usr/lib/python3.4/site-packages/django/apps/config.py", line 123, in create
    import_module(entry)
  File "/usr/lib64/python3.4/importlib/__init__.py", line 109, in import_module
    return _bootstrap._gcd_import(name[level:], package, level)
  File "<frozen importlib._bootstrap>", line 2254, in _gcd_import
  File "<frozen importlib._bootstrap>", line 2237, in _find_and_load
  File "<frozen importlib._bootstrap>", line 2221, in _find_and_load_unlocked
ImportError: No module named 'homebase.apps.homebaseConfig'; 'homebase.apps' is not a package
Unhandled exception in thread started by <function check_errors.<locals>.wrapper at 0x7fd404a26bf8>
Traceback (most recent call last):
  File "/usr/lib/python3.4/site-packages/django/db/backends/postgresql/base.py", line 20, in <module>
    import psycopg2 as Database
ImportError: No module named 'psycopg2'

During handling of the above exception, another exception occurred:

Traceback (most recent call last):
  File "/usr/lib/python3.4/site-packages/django/utils/autoreload.py", line 226, in wrapper
    fn(*args, **kwargs)
  File "/usr/lib/python3.4/site-packages/django/core/management/commands/runserver.py", line 109, in inner_run
    autoreload.raise_last_exception()
  File "/usr/lib/python3.4/site-packages/django/utils/autoreload.py", line 249, in raise_last_exception
    six.reraise(*_exception)
  File "/usr/lib/python3.4/site-packages/django/utils/six.py", line 685, in reraise
    raise value.with_traceback(tb)
  File "/usr/lib/python3.4/site-packages/django/utils/autoreload.py", line 226, in wrapper
    fn(*args, **kwargs)
  File "/usr/lib/python3.4/site-packages/django/__init__.py", line 18, in setup
    apps.populate(settings.INSTALLED_APPS)
  File "/usr/lib/python3.4/site-packages/django/apps/registry.py", line 108, in populate
    app_config.import_models(all_models)
  File "/usr/lib/python3.4/site-packages/django/apps/config.py", line 202, in import_models
    self.models_module = import_module(models_module_name)
  File "/usr/lib64/python3.4/importlib/__init__.py", line 109, in import_module
    return _bootstrap._gcd_import(name[level:], package, level)
  File "<frozen importlib._bootstrap>", line 2254, in _gcd_import
  File "<frozen importlib._bootstrap>", line 2237, in _find_and_load
  File "<frozen importlib._bootstrap>", line 2226, in _find_and_load_unlocked
  File "<frozen importlib._bootstrap>", line 1200, in _load_unlocked
  File "<frozen importlib._bootstrap>", line 1129, in _exec
  File "<frozen importlib._bootstrap>", line 1471, in exec_module
  File "<frozen importlib._bootstrap>", line 321, in _call_with_frames_removed
  File "/home/alex/Dropbox/Workdir/CI103/homebase/models.py", line 6, in <module>
    class User(models.Model):
  File "/usr/lib/python3.4/site-packages/django/db/models/base.py", line 108, in __new__
    new_class.add_to_class('_meta', Options(meta, app_label))
  File "/usr/lib/python3.4/site-packages/django/db/models/base.py", line 307, in add_to_class
    value.contribute_to_class(cls, name)
  File "/usr/lib/python3.4/site-packages/django/db/models/options.py", line 263, in contribute_to_class
    self.db_table = truncate_name(self.db_table, connection.ops.max_name_length())
  File "/usr/lib/python3.4/site-packages/django/db/__init__.py", line 36, in __getattr__
    return getattr(connections[DEFAULT_DB_ALIAS], item)
  File "/usr/lib/python3.4/site-packages/django/db/utils.py", line 212, in __getitem__
    backend = load_backend(db['ENGINE'])
  File "/usr/lib/python3.4/site-packages/django/db/utils.py", line 116, in load_backend
    return import_module('%s.base' % backend_name)
  File "/usr/lib64/python3.4/importlib/__init__.py", line 109, in import_module
    return _bootstrap._gcd_import(name[level:], package, level)
  File "<frozen importlib._bootstrap>", line 2254, in _gcd_import
  File "<frozen importlib._bootstrap>", line 2237, in _find_and_load
  File "<frozen importlib._bootstrap>", line 2226, in _find_and_load_unlocked
  File "<frozen importlib._bootstrap>", line 1200, in _load_unlocked
  File "<frozen importlib._bootstrap>", line 1129, in _exec
  File "<frozen importlib._bootstrap>", line 1471, in exec_module
  File "<frozen importlib._bootstrap>", line 321, in _call_with_frames_removed
  File "/usr/lib/python3.4/site-packages/django/db/backends/postgresql/base.py", line 24, in <module>
    raise ImproperlyConfigured("Error loading psycopg2 module: %s" % e)
django.core.exceptions.ImproperlyConfigured: Error loading psycopg2 module: No module named 'psycopg2'
